<?xml version="1.0" ?>
<robot name="Robot">
  <!--Generated by CROSS, a ROS Workbench for FreeCAD (https://github.com/galou/freecad.cross)-->
  <link name="base_link">
    <inertial>
      <mass value="0.1"/>
      <origin xyz="0.0 0.0 0.0" rpy="0.0 -0.0 0.0"/>
      <inertia ixx="0.01" ixy="0.0" ixz="0.0" iyy="0.01" iyz="0.0" izz="0.0"/>
    </inertial>
  </link>
  <link name="servo">
    <visual>
      <!--servo002-->
      <origin xyz="-0.0235 0.0119 0.0176" rpy="0.0 -0.0 0.0"/>
      <geometry>
        <mesh filename="package://yahboom_camera_controller/meshes/Camera_servo002.dae"/>
      </geometry>
    </visual>
    <collision>
      <!--servo002_bbox-->
      <origin xyz="0.00016 -0.00035 0.014855" rpy="0.0 -0.0 0.0"/>
      <geometry>
        <box size="0.03210000000000001 0.012400000000002187 0.02995"/>
      </geometry>
    </collision>
    <inertial>
      <mass value="0.009000000000000001"/>
      <origin xyz="0.0 0.0 0.0" rpy="0.0 -0.0 0.0"/>
      <inertia ixx="0.02" ixy="0.0" ixz="0.0" iyy="0.01" iyz="0.0" izz="0.02"/>
    </inertial>
  </link>
  <link name="servo_mount">
    <visual>
      <!--servo_mount001-->
      <origin xyz="-0.0185 0.01191 -0.0125" rpy="0.0 -0.0 0.0"/>
      <geometry>
        <mesh filename="package://yahboom_camera_controller/meshes/Camera_servo_mount001.dae"/>
      </geometry>
    </visual>
    <collision>
      <!--servo_mount001_bbox-->
      <origin xyz="1e-05 -0.00035 -0.00142" rpy="0.0 -0.0 0.0"/>
      <geometry>
        <box size="0.0320728250575205 0.0069000000000000025 0.0038000000000000026"/>
      </geometry>
    </collision>
    <inertial>
      <mass value="0.001"/>
      <origin xyz="0.0 0.0 0.0" rpy="0.0 -0.0 0.0"/>
      <inertia ixx="0.009999999999999787" ixy="0.0" ixz="0.0" iyy="0.01" iyz="0.0" izz="0.01"/>
    </inertial>
  </link>
  <link name="bottom">
    <visual>
      <!--bottom_part/Body001.-->
      <origin xyz="-0.0185 0.01215 -0.01252" rpy="0.0 -0.0 0.0"/>
      <geometry>
        <mesh filename="package://yahboom_camera_controller/meshes/Camera_bottom.dae"/>
      </geometry>
    </visual>
    <collision>
      <!--bottom_part/Body001.-->
      <origin xyz="-0.0185 0.01215 -0.01252" rpy="0.0 -0.0 0.0"/>
      <geometry>
        <mesh filename="package://yahboom_camera_controller/meshes/Camera_bottom.dae"/>
      </geometry>
    </collision>
    <inertial>
      <mass value="0.001"/>
      <origin xyz="0.0 0.0 0.0" rpy="0.0 -0.0 0.0"/>
      <inertia ixx="0.02" ixy="0.0" ixz="0.0" iyy="0.02" iyz="0.0" izz="0.02"/>
    </inertial>
  </link>
  <link name="connecting_rod">
    <visual>
      <!--Connecting rod001/Body004.-->
      <origin xyz="-0.04088 -0.00305 0.0185" rpy="-0.0 1.5707963267948966 0.0"/>
      <geometry>
        <mesh filename="package://yahboom_camera_controller/meshes/Camera_Connecting_rod.dae"/>
      </geometry>
    </visual>
    <collision>
      <!--Connecting rod001.Body004_bbox-->
      <origin xyz="0.00012 -0.000108672 -0.00025" rpy="-0.0 1.5707963267948966 0.0"/>
      <geometry>
        <box size="0.05169999999999999 0.008000000000000004 0.007956175162946237"/>
      </geometry>
    </collision>
    <inertial>
      <mass value="0.001"/>
      <origin xyz="0.0 0.0 0.0" rpy="0.0 -0.0 0.0"/>
      <inertia ixx="0.1" ixy="0.0" ixz="0.0" iyy="0.1" iyz="0.0" izz="0.1"/>
    </inertial>
  </link>
  <link name="top_part">
    <visual>
      <!--Top Part/Body003.-->
      <origin xyz="-0.01925 -0.00305 -0.04112" rpy="0.0 -0.0 0.0"/>
      <geometry>
        <mesh filename="package://yahboom_camera_controller/meshes/Camera_top.dae"/>
      </geometry>
    </visual>
    <collision>
      <!--Top Part/Body003.-->
      <origin xyz="-0.01925 -0.00305 -0.04112" rpy="0.0 -0.0 0.0"/>
      <geometry>
        <mesh filename="package://yahboom_camera_controller/meshes/Camera_top.dae"/>
      </geometry>
    </collision>
    <inertial>
      <mass value="0.01"/>
      <origin xyz="0.0 0.0 0.0" rpy="0.0 -0.0 0.0"/>
      <inertia ixx="0.1" ixy="0.0" ixz="0.0" iyy="0.1" iyz="0.0" izz="0.1"/>
    </inertial>
  </link>
  <link name="camera_lens">
    <visual>
      <!--Lens-->
      <origin xyz="-0.01925 -0.0381 -0.0371" rpy="0.0 -0.0 0.0"/>
      <geometry>
        <mesh filename="package://yahboom_camera_controller/meshes/Camera_Lens.dae"/>
      </geometry>
    </visual>
    <collision>
      <!--Lens_bbox-->
      <origin xyz="-0.00025 0.00395 -9.66852e-05" rpy="0.0 -0.0 0.0"/>
      <geometry>
        <box size="0.009996684675143133 0.00010000000000003695 0.009993370449424156"/>
      </geometry>
    </collision>
    <inertial>
      <mass value="0.001"/>
      <origin xyz="0.0 0.0 0.0" rpy="0.0 -0.0 0.0"/>
      <inertia ixx="0.01" ixy="0.0" ixz="0.0" iyy="0.01" iyz="0.0" izz="0.01"/>
    </inertial>
  </link>
  <joint name="base_link_servo_joint" type="fixed">
    <parent link="base_link"/>
    <child link="servo"/>
    <origin xyz="0.0 0.0 0.0" rpy="0.0 -0.0 0.0"/>
  </joint>
  <joint name="servo_to_mount" type="revolute">
    <parent link="servo"/>
    <child link="servo_mount"/>
    <origin xyz="-0.005 0.0 0.03055" rpy="0.0 -0.0 0.0"/>
    <axis xyz="0 0 1"/>
    <limit lower="-1.5707963267948966" upper="1.5707963267948966" velocity="0.0" effort="0.0"/>
  </joint>
  <joint name="mount_to_bottom" type="fixed">
    <parent link="servo_mount"/>
    <child link="bottom"/>
    <origin xyz="0.0 0.0 0.0" rpy="0.0 -0.0 0.0"/>
  </joint>
  <joint name="bottom_to_connecting_rod" type="revolute">
    <parent link="bottom"/>
    <child link="connecting_rod"/>
    <origin xyz="0.0 0.0152 0.0286" rpy="-0.0 1.5707963267948966 0.0"/>
    <axis xyz="0 0 1"/>
    <limit lower="-1.5707963267948966" upper="1.5707963267948966" velocity="0.0" effort="0.0"/>
  </joint>
  <joint name="connecting_rod_top" type="fixed">
    <parent link="connecting_rod"/>
    <child link="top_part"/>
    <origin xyz="0.0 0.0 0.0" rpy="-0.0 -1.5707963267948961 0.0"/>
  </joint>
  <joint name="top_to_camera" type="fixed">
    <parent link="top_part"/>
    <child link="camera_lens"/>
    <origin xyz="0.0 0.035 -0.004" rpy="0.0 -0.0 0.0"/>
  </joint>
</robot>
