<?xml version="1.0" ?>
<robot name="Robot">
  <!--Generated by CROSS, a ROS Workbench for FreeCAD (https://github.com/galou/freecad.cross)-->
  <link name="base_link">
    <inertial>
      <mass value="0.0"/>
      <origin xyz="0.0 0.0 0.0" rpy="0.0 -0.0 0.0"/>
      <inertia ixx="0.0" ixy="0.0" ixz="0.0" iyy="0.0" iyz="0.0" izz="0.0"/>
    </inertial>
  </link>
  <link name="servo">
    <visual>
      <!--servo002-->
      <origin xyz="0.0 0.02 0.02" rpy="0.0 -0.0 0.0"/>
      <geometry>
        <mesh filename="package://camera/meshes/Camera_servo002.dae"/>
      </geometry>
    </visual>
    <collision>
      <!--servo002-->
      <origin xyz="0.0 0.02 0.02" rpy="0.0 -0.0 0.0"/>
      <geometry>
        <mesh filename="package://camera/meshes/Camera_servo002.dae"/>
      </geometry>
    </collision>
    <inertial>
      <mass value="0.0"/>
      <origin xyz="0.0 0.0 0.0" rpy="0.0 -0.0 0.0"/>
      <inertia ixx="0.0" ixy="0.0" ixz="0.0" iyy="0.0" iyz="0.0" izz="0.0"/>
    </inertial>
  </link>
  <link name="servo_mount">
    <visual>
      <!--servo_mount001-->
      <origin xyz="-0.01851 0.0125 -0.0135" rpy="0.0 -0.0 0.0"/>
      <geometry>
        <mesh filename="package://camera/meshes/Camera_servo_mount001.dae"/>
      </geometry>
    </visual>
    <collision>
      <!--servo_mount001-->
      <origin xyz="-0.01851 0.0125 -0.0135" rpy="0.0 -0.0 0.0"/>
      <geometry>
        <mesh filename="package://camera/meshes/Camera_servo_mount001.dae"/>
      </geometry>
    </collision>
    <inertial>
      <mass value="0.0"/>
      <origin xyz="0.0 0.0 0.0" rpy="0.0 -0.0 0.0"/>
      <inertia ixx="0.0" ixy="0.0" ixz="0.0" iyy="0.0" iyz="0.0" izz="0.0"/>
    </inertial>
  </link>
  <link name="bottom">
    <visual>
      <!--bottom_part/Body001.-->
      <origin xyz="-0.0185 0.0123 -0.0135" rpy="0.0 -0.0 0.0"/>
      <geometry>
        <mesh filename="package://camera/meshes/Camera_bottom.dae"/>
      </geometry>
    </visual>
    <collision>
      <!--bottom_part/Body001.-->
      <origin xyz="-0.0185 0.0123 -0.0135" rpy="0.0 -0.0 0.0"/>
      <geometry>
        <mesh filename="package://camera/meshes/Camera_bottom.dae"/>
      </geometry>
    </collision>
    <inertial>
      <mass value="0.0"/>
      <origin xyz="0.0 0.0 0.0" rpy="0.0 -0.0 0.0"/>
      <inertia ixx="0.0" ixy="0.0" ixz="0.0" iyy="0.0" iyz="0.0" izz="0.0"/>
    </inertial>
  </link>
  <link name="conneecting_rod">
    <visual>
      <!--Connecting rod001/Body004.-->
      <origin xyz="0.0 0.012 -0.04" rpy="0.0 -0.0 0.0"/>
      <geometry>
        <mesh filename="package://camera/meshes/Camera_Connecting_rod.dae"/>
      </geometry>
    </visual>
    <collision>
      <!--Connecting rod001/Body004.-->
      <origin xyz="0.0 0.012 -0.04" rpy="0.0 -0.0 0.0"/>
      <geometry>
        <mesh filename="package://camera/meshes/Camera_Connecting_rod.dae"/>
      </geometry>
    </collision>
    <inertial>
      <mass value="0.0"/>
      <origin xyz="0.0 0.0 0.0" rpy="0.0 -0.0 0.0"/>
      <inertia ixx="0.0" ixy="0.0" ixz="0.0" iyy="0.0" iyz="0.0" izz="0.0"/>
    </inertial>
  </link>
  <link name="top_part">
    <visual>
      <!--Top Part/Body003.-->
      <origin xyz="0.041 -0.003 0.0" rpy="-0.0 -1.5707963267948961 0.0"/>
      <geometry>
        <mesh filename="package://camera/meshes/Camera_top.dae"/>
      </geometry>
    </visual>
    <collision>
      <!--Top Part/Body003.-->
      <origin xyz="0.041 -0.003 0.0" rpy="-0.0 -1.5707963267948961 0.0"/>
      <geometry>
        <mesh filename="package://camera/meshes/Camera_top.dae"/>
      </geometry>
    </collision>
    <inertial>
      <mass value="0.0"/>
      <origin xyz="0.0 0.0 0.0" rpy="0.0 -0.0 0.0"/>
      <inertia ixx="0.0" ixy="0.0" ixz="0.0" iyy="0.0" iyz="0.0" izz="0.0"/>
    </inertial>
  </link>
  <link name="Lens">
    <visual>
      <!--Lens-->
      <origin xyz="-0.019 -0.043 -0.037" rpy="0.0 -0.0 0.0"/>
      <geometry>
        <mesh filename="package://camera/meshes/Camera_Lens.dae"/>
      </geometry>
    </visual>
    <collision>
      <!--Lens-->
      <origin xyz="-0.019 -0.043 -0.037" rpy="0.0 -0.0 0.0"/>
      <geometry>
        <mesh filename="package://camera/meshes/Camera_Lens.dae"/>
      </geometry>
    </collision>
    <inertial>
      <mass value="0.0"/>
      <origin xyz="0.0 0.0 0.0" rpy="0.0 -0.0 0.0"/>
      <inertia ixx="0.0" ixy="0.0" ixz="0.0" iyy="0.0" iyz="0.0" izz="0.0"/>
    </inertial>
  </link>
  <joint name="base_to_servo" type="fixed">
    <parent link="base_link"/>
    <child link="servo"/>
    <origin xyz="0.0 0.0 0.0" rpy="0.0 -0.0 0.0"/>
  </joint>
  <joint name="servo_to_mount" type="revolute">
    <parent link="servo"/>
    <child link="servo_mount"/>
    <origin xyz="0.01851 0.00775 0.03338" rpy="0.0 -0.0 3.141592653589793"/>
    <axis xyz="0 0 1"/>
    <limit lower="-1.5707963267948966" upper="1.5707963267948966" velocity="0.017453292519943295" effort="5.0"/>
  </joint>
  <joint name="mount_to_bottom" type="fixed">
    <parent link="servo_mount"/>
    <child link="bottom"/>
    <origin xyz="0.0 0.0 0.0" rpy="0.0 -0.0 3.141592653589793"/>
  </joint>
  <joint name="bottom_to_connecting_rod" type="fixed">
    <parent link="bottom"/>
    <child link="conneecting_rod"/>
    <origin xyz="-0.0187 0.0003 0.0265" rpy="0.0 -0.0 0.0"/>
  </joint>
  <joint name="connecting_rod_to_top_part" type="revolute">
    <parent link="conneecting_rod"/>
    <child link="top_part"/>
    <origin xyz="0.0 0.015 0.001" rpy="-0.0 1.5707963267948966 0.0"/>
    <axis xyz="0 0 1"/>
    <limit lower="-1.5707963267948966" upper="1.5707963267948966" velocity="0.017453292519943295" effort="5.0"/>
  </joint>
  <joint name="top_to_lens" type="fixed">
    <parent link="top_part"/>
    <child link="Lens"/>
    <origin xyz="0.004 0.04 0.019" rpy="0.0 -0.0 0.0"/>
  </joint>
</robot>
